<?xml version="1.0"?>
<!--
  Robot:      easybot
  Drive type: 4-Wheel Skid-Steer
  Generated:  2026-06-25T05:10:31.113Z
  Tool:       Easy Way to Make a URDF (https://github.com/easywayurdf)
  Convention: ROS REP-103 — X-forward, Y-left, Z-up
-->
<robot name="easybot" xmlns:xacro="http://ros.org/wiki/xacro">

  <!-- ═══════════════════════════════════════════════
       MATERIALS
  ═══════════════════════════════════════════════ -->
    <material name="chassis_material">
      <color rgba="0.29 0.36 0.68 1.0"/>
    </material>
    <material name="wheel_material">
      <color rgba="0.10 0.12 0.18 1.0"/>
    </material>
    <material name="caster_material">
      <color rgba="0.53 0.53 0.53 1.0"/>
    </material>
    <material name="lidar_material">
      <color rgba="1.0 1.0 1.0 1.0"/>
    </material>
    <material name="camera_material">
      <color rgba="0.02 0.84 0.63 1.0"/>
    </material>
    <material name="depth_camera_material">
      <color rgba="0.07 0.54 0.70 1.0"/>
    </material>
    <material name="imu_material">
      <color rgba="0.94 0.28 0.44 1.0"/>
    </material>

  <!-- ═══════════════════════════════════════════════
       LINKS
  ═══════════════════════════════════════════════ -->
    <!-- base_link: virtual root, position at ground contact point -->
    <link name="base_link"/>
    <link name="chassis">
      <inertial>
        <origin xyz="0 0 0" rpy="0 0 0"/>
        <mass value="4.000000"/>
        <inertia ixx="0.016033" ixy="0.000000" ixz="0.000000"
                 iyy="0.023533" iyz="0.000000"
                 izz="0.034167"/>
      </inertial>
      <visual>
        <origin xyz="0 0 0" rpy="0 0 0"/>
        <geometry>
          <box size="0.250000 0.200000 0.090000"/>
        </geometry>
        <material name="chassis_material"/>
      </visual>
      <collision>
        <origin xyz="0 0 0" rpy="0 0 0"/>
        <geometry>
          <box size="0.250000 0.200000 0.090000"/>
        </geometry>
      </collision>
    </link>
    <link name="front_left_wheel">
      <inertial>
        <origin xyz="0 0 0" rpy="0 0 0"/>
        <mass value="0.250000"/>
        <inertia ixx="0.000082" ixy="0.000000" ixz="0.000000"
                 iyy="0.000082" iyz="0.000000"
                 izz="0.000136"/>
      </inertial>
      <visual>
        <origin xyz="0 0 0" rpy="1.5707963 0 0"/>
        <geometry>
          <cylinder radius="0.033000" length="0.026000"/>
        </geometry>
        <material name="wheel_material"/>
      </visual>
      <collision>
        <origin xyz="0 0 0" rpy="1.5707963 0 0"/>
        <geometry>
          <cylinder radius="0.033000" length="0.026000"/>
        </geometry>
      </collision>
    </link>
    <link name="front_right_wheel">
      <inertial>
        <origin xyz="0 0 0" rpy="0 0 0"/>
        <mass value="0.250000"/>
        <inertia ixx="0.000082" ixy="0.000000" ixz="0.000000"
                 iyy="0.000082" iyz="0.000000"
                 izz="0.000136"/>
      </inertial>
      <visual>
        <origin xyz="0 0 0" rpy="1.5707963 0 0"/>
        <geometry>
          <cylinder radius="0.033000" length="0.026000"/>
        </geometry>
        <material name="wheel_material"/>
      </visual>
      <collision>
        <origin xyz="0 0 0" rpy="1.5707963 0 0"/>
        <geometry>
          <cylinder radius="0.033000" length="0.026000"/>
        </geometry>
      </collision>
    </link>
    <link name="rear_left_wheel">
      <inertial>
        <origin xyz="0 0 0" rpy="0 0 0"/>
        <mass value="0.250000"/>
        <inertia ixx="0.000082" ixy="0.000000" ixz="0.000000"
                 iyy="0.000082" iyz="0.000000"
                 izz="0.000136"/>
      </inertial>
      <visual>
        <origin xyz="0 0 0" rpy="1.5707963 0 0"/>
        <geometry>
          <cylinder radius="0.033000" length="0.026000"/>
        </geometry>
        <material name="wheel_material"/>
      </visual>
      <collision>
        <origin xyz="0 0 0" rpy="1.5707963 0 0"/>
        <geometry>
          <cylinder radius="0.033000" length="0.026000"/>
        </geometry>
      </collision>
    </link>
    <link name="rear_right_wheel">
      <inertial>
        <origin xyz="0 0 0" rpy="0 0 0"/>
        <mass value="0.250000"/>
        <inertia ixx="0.000082" ixy="0.000000" ixz="0.000000"
                 iyy="0.000082" iyz="0.000000"
                 izz="0.000136"/>
      </inertial>
      <visual>
        <origin xyz="0 0 0" rpy="1.5707963 0 0"/>
        <geometry>
          <cylinder radius="0.033000" length="0.026000"/>
        </geometry>
        <material name="wheel_material"/>
      </visual>
      <collision>
        <origin xyz="0 0 0" rpy="1.5707963 0 0"/>
        <geometry>
          <cylinder radius="0.033000" length="0.026000"/>
        </geometry>
      </collision>
    </link>

    <link name="lidar_1">
      <inertial>
        <origin xyz="0 0 0" rpy="0 0 0"/>
        <mass value="0.200000"/>
        <inertia ixx="0.000222" ixy="0.000000" ixz="0.000000"
                 iyy="0.000222" iyz="0.000000"
                 izz="0.000270"/>
      </inertial>
      <visual>
        <origin xyz="0 0 0" rpy="0 0 0"/>
        <geometry>
          <cylinder radius="0.052000" length="0.072000"/>
        </geometry>
        <material name="lidar_material"/>
      </visual>
      <collision>
        <origin xyz="0 0 0" rpy="0 0 0"/>
        <geometry>
          <cylinder radius="0.052000" length="0.072000"/>
        </geometry>
      </collision>
    </link>

  <!-- ═══════════════════════════════════════════════
       JOINTS
  ═══════════════════════════════════════════════ -->
    <joint name="base_link_to_chassis" type="fixed">
      <parent link="base_link"/>
      <child link="chassis"/>
      <origin xyz="0.000000 0.000000 0.058000" rpy="0.000000 0.000000 0.000000"/>
    </joint>
    <joint name="chassis_to_front_left_wheel" type="continuous">
      <parent link="chassis"/>
      <child link="front_left_wheel"/>
      <origin xyz="0.090000 0.120000 -0.058000" rpy="0.000000 0.000000 0.000000"/>
      <axis xyz="0 1 0"/>
    </joint>
    <joint name="chassis_to_front_right_wheel" type="continuous">
      <parent link="chassis"/>
      <child link="front_right_wheel"/>
      <origin xyz="0.090000 -0.120000 -0.058000" rpy="0.000000 0.000000 0.000000"/>
      <axis xyz="0 1 0"/>
    </joint>
    <joint name="chassis_to_rear_left_wheel" type="continuous">
      <parent link="chassis"/>
      <child link="rear_left_wheel"/>
      <origin xyz="-0.090000 0.120000 -0.058000" rpy="0.000000 0.000000 0.000000"/>
      <axis xyz="0 1 0"/>
    </joint>
    <joint name="chassis_to_rear_right_wheel" type="continuous">
      <parent link="chassis"/>
      <child link="rear_right_wheel"/>
      <origin xyz="-0.090000 -0.120000 -0.058000" rpy="0.000000 0.000000 0.000000"/>
      <axis xyz="0 1 0"/>
    </joint>
    <joint name="chassis_to_lidar_1" type="fixed">
      <parent link="chassis"/>
      <child link="lidar_1"/>
      <origin xyz="0.000000 0.000000 0.055000" rpy="0.000000 0.000000 0.000000"/>
    </joint>


    <!-- ═══════════════════════════════════════════════
       Archivo que conecta con el xacro de gazebo para realizar la simulacion
  ═══════════════════════════════════════════════ -->
  <xacro:include filename="easybot_gazebo.xacro" />

</robot>
